multiprocessing.pool.RemoteTraceback: 
"""
Traceback (most recent call last):
  File "/gpfs/software/Anaconda/envs/python/lib/python3.9/multiprocessing/pool.py", line 125, in worker
    result = (True, func(*args, **kwds))
  File "/gpfs/software/Anaconda/envs/python/lib/python3.9/multiprocessing/pool.py", line 48, in mapstar
    return list(map(*args))
  File "/gpfs/projects/RestGroup/keffy/clean_pipeline_plants/cluster_scripts/rna_protein_faster.py", line 50, in greppin
    rna = get_rna.split('Parent=rna-')[1]
IndexError: list index out of range
"""

The above exception was the direct cause of the following exception:

Traceback (most recent call last):
  File "/gpfs/projects/RestGroup/keffy/clean_pipeline_plants/cluster_scripts/rna_protein_faster.py", line 59, in <module>
    pool.map(greppin, ogs)
  File "/gpfs/software/Anaconda/envs/python/lib/python3.9/multiprocessing/pool.py", line 364, in map
    return self._map_async(func, iterable, mapstar, chunksize).get()
  File "/gpfs/software/Anaconda/envs/python/lib/python3.9/multiprocessing/pool.py", line 771, in get
    raise self._value
IndexError: list index out of range
